[2025-10-04 12:39:11,124][DEBUG|lsfrealtime.py:414] =>> lsmainloop() exception!!
[2025-10-04 12:39:11,125][DEBUG|lsfrealtime.py:416] =>> Connect Again!!
[2025-10-04 12:39:41,260][DEBUG|lsfrealtime.py:414] =>> lsmainloop() exception!!
[2025-10-04 12:39:41,260][DEBUG|lsfrealtime.py:416] =>> Connect Again!!
[2025-10-04 12:40:11,405][DEBUG|lsfrealtime.py:414] =>> lsmainloop() exception!!
[2025-10-04 12:40:11,405][DEBUG|lsfrealtime.py:416] =>> Connect Again!!
[2025-10-04 12:40:41,576][DEBUG|lsfrealtime.py:414] =>> lsmainloop() exception!!
[2025-10-04 12:40:41,577][DEBUG|lsfrealtime.py:416] =>> Connect Again!!
[2025-10-04 12:41:11,795][DEBUG|lsfrealtime.py:414] =>> lsmainloop() exception!!
[2025-10-04 12:41:11,796][DEBUG|lsfrealtime.py:416] =>> Connect Again!!
[2025-10-04 12:41:41,924][DEBUG|lsfrealtime.py:414] =>> lsmainloop() exception!!
[2025-10-04 12:41:41,925][DEBUG|lsfrealtime.py:416] =>> Connect Again!!
[2025-10-04 12:42:12,159][DEBUG|lsfrealtime.py:414] =>> lsmainloop() exception!!
[2025-10-04 12:42:12,160][DEBUG|lsfrealtime.py:416] =>> Connect Again!!
[2025-10-04 12:42:42,298][DEBUG|lsfrealtime.py:414] =>> lsmainloop() exception!!
[2025-10-04 12:42:42,299][DEBUG|lsfrealtime.py:416] =>> Connect Again!!
[2025-10-04 12:43:12,490][DEBUG|lsfrealtime.py:414] =>> lsmainloop() exception!!
[2025-10-04 12:43:12,491][DEBUG|lsfrealtime.py:416] =>> Connect Again!!
[2025-10-04 12:43:42,911][DEBUG|lsfrealtime.py:414] =>> lsmainloop() exception!!
[2025-10-04 12:43:42,911][DEBUG|lsfrealtime.py:416] =>> Connect Again!!
[2025-10-04 12:44:13,046][DEBUG|lsfrealtime.py:414] =>> lsmainloop() exception!!
[2025-10-04 12:44:13,046][DEBUG|lsfrealtime.py:416] =>> Connect Again!!
[2025-10-04 12:44:43,405][DEBUG|lsfrealtime.py:414] =>> lsmainloop() exception!!
[2025-10-04 12:44:43,405][DEBUG|lsfrealtime.py:416] =>> Connect Again!!
[2025-10-04 12:45:13,542][DEBUG|lsfrealtime.py:414] =>> lsmainloop() exception!!
[2025-10-04 12:45:13,542][DEBUG|lsfrealtime.py:416] =>> Connect Again!!
[2025-10-04 12:45:43,723][DEBUG|lsfrealtime.py:414] =>> lsmainloop() exception!!
[2025-10-04 12:45:43,723][DEBUG|lsfrealtime.py:416] =>> Connect Again!!
